Workbook

Sheet Sheet3
B1: LAPORAN POSISI KEUANGAN
B2: PEKERJAAN RUMAH MISSISSIPPI TE5 NO 8 KOWIS
A4: TANGGAL | B4: NO | C4: KETERANGAN | D4: BUDGET | E4: TERIMA | F4: SALDO | G4: TUKANG BESI | H4: TUKANG +KENEK | I4: MANDOR | J4: PER HARI
A6: 45724 | B6: I | C6: BIAYA PEMBANGUNAN RUMAH | D6: =REKAP!D30 -> 148000000
A8: 45784 | C8: Kas Bon mas Tikno Tk.Besi | G8: 4000000
A9: 45784 | B9: 1 | C9: Kas Bon Mandor Sata Cs | E9: 9200000 | H9: =875000+700000+960000+1050000+840000+700000+840000+280000 -> 6245000 | I9: =E9-H9 -> 2955000
A10: 45998 | B10: 2 | C10: Kas Bon Mandor Sata Cs | E10: 8245000 | H10: =875000+700000+960000+1050000+840000+700000+840000+280000 -> 6245000 | I10: =E10-H10 -> 2000000 | J10: =I10/6 -> 333333.33
A11: 19/7/2025 | C11: Kas Bon mas Tikno Tk.Besi | G11: 2000000
A12: 19/7/2025 | B12: 3 | C12: Kas Bon Mandor Sata Cs | E12: 9325000 | H12: =875000+1050000+1050000+990000+(840000*4) -> 7325000 | I12: =E12-H12 -> 2000000 | J12: =I12/6 -> 333333.33
A13: 26/7/2025 | C13: Kas Bon mas Tikno Tk.Besi | G13: 3000000
A14: 26/7/2025 | B14: 4 | C14: Kas Bon Mandor Sata Cs | E14: 10300000 | H14: =875000+1050000+1050000+990000+(840000*4) -> 7325000 | I14: =E14-H14 -> 2975000 | J14: =I14/6 -> 495833.33
B15: 8 | C15: Kas Bon mas Tikno Tk.Besi | G15: 1000000
A16: 45696 | B16: 9 | C16: Kas Bon Mandor Sata Cs | E16: 9445000 | H16: =1050000+875000+1050000+990000+960000+(840000*3) -> 7445000 | I16: =E16-H16 -> 2000000 | J16: =I16/6 -> 333333.33
A17: 45908 | B17: 10 | C17: Kas Bon mas Tikno Tk.Besi | G17: 2500000
A18: 20/8/2025 | B18: 11 | C18: Kas Bon | E18: 1000000 | I18: 1000000
A19: 45908 | B19: 12 | C19: Kas Bon Mandor Sata Cs | E19: 9445000 | H19: =1050000+875000+1050000+990000+960000+840000+840000+840000 -> 7445000 | I19: =E19-H19 -> 2000000 | J19: =I19/6 -> 333333.33
A20: 15/8/2025 | B20: 13 | C20: Kas Bon Mandor Sata Cs | E20: 9375000 | H20: =700000+875000+875000+825000+800000+(700000*4) -> 6875000 | I20: =E20-H20 -> 2500000 | J20: =I20/5 -> 500000
A21: 16/8/2025 | B21: 14 | C21: Kas Bon mas Tikno Tk.Besi | G21: 500000
A22: 23/8/2027 | B22: 15 | C22: Kas Bon Mandor Sata Cs | E22: 7060000 | H22: =700000+700000+700000+660000+640000+(540000*4) -> 5560000 | I22: =E22-H22 -> 1500000 | J22: =I22/4 -> 375000
A23: 30/8/2025 | B23: 16 | C23: Kas Bon Mandor Sata Cs | E23: 10960000 | H23: =1050000+1050000+1050000+990000+960000+840000+840000+840000+840000 -> 8460000 | I23: =E23-H23 -> 2500000 | J23: =I23/6 -> 416666.67
A24: 30/8/2025 | B24: 17 | C24: Kas Bon mas Tikno Tk.Besi | G24: 1000000
A25: 45817 | B25: 18 | C25: Kas Bon Mandor Sata Cs | E25: 8655000 | H25: =850000+850000+825000+850000+480000+700000+700000+700000+700000 -> 6655000 | I25: =E25-H25 -> 2000000 | J25: =I25/5 -> 400000
A26: 45817 | B26: 19 | C26: Kas Bon mas Tikno Tk.Besi | G26: 1000000
A27: 13/9/2025 | B27: 20 | C27: Kas Bon Mandor Sata Cs | E27: 10465000 | H27: =1050000+1050000+1050000+1000000+525000+850000+840000+840000+810000 -> 8015000 | I27: =E27-H27 -> 2450000 | J27: =I27/6 -> 408333.33
A28: 13/9/2025 | B28: 21 | C28: Kas Bon mas Tikno Tk.Besi | G28: 1500000
A29: 20/9/2025 | B29: 22 | C29: Kas Bon Mandor Sata Cs | E29: 11000000 | H29: =1050000+1050000+1000000+1050000+960000+840000+840000+840000+840000 -> 8470000 | I29: =E29-H29 -> 2530000 | J29: =I29/6 -> 421666.67
A30: 27/9/2025 | B30: 23 | C30: Kas Bon Mandor Sata Cs | E30: 11020000 | H30: =1050000+1050000+1000000+960000+1050000+840000+840000+840000+840000 -> 8470000 | I30: =E30-H30 -> 2550000 | J30: =I30/6 -> 425000
A31: 45757 | B31: 24 | C31: Kas Bon Mandor Sata Cs | E31: 10970000 | H31: =1050000+1050000+1000000+1050000+960000+840000+840000+840000+840000 -> 8470000 | I31: =E31-H31 -> 2500000 | J31: =I31/6 -> 416666.67
A32: 45971 | B32: 25 | C32: Kas Bon Mandor Sata Cs | E32: 8950000 | H32: =1050000+1050000+350000+1000000+480000+840000+840000+840000 -> 6450000 | I32: =E32-H32 -> 2500000 | J32: =I32/6 -> 416666.67
A33: 18/10/2025 | B33: 26 | C33: Kas Bon Mandor Sata Cs | E33: 9255000 | H33: =650000+1050000+1000000+960000+840000+840000+840000+175000 -> 6355000 | I33: =E33-H33 -> 2900000 | J33: =I33/6 -> 483333.33
A34: 25/10/2025 | B34: 27 | C34: Kas Bon Mandor Sata Cs | E34: 7500000 | H34: =E34-I34 -> 5580000 | I34: 1920000 | J34: =I34/6 -> 320000
G35: =SUM(G6:G34) -> 16500000 | H35: =SUM(H8:H34) -> 121390000 | I35: =SUM(I9:I34) -> 40780000
A36: TOTAL | D36: =SUM(D6:D35) -> 148000000 | E36: =SUM(E8:E34) -> 162170000 | F36: =D36-E36 -> -14170000 | H36: =H35/E36% -> 74.853549 | I36: =I35/E36% -> 25.146451
B40: Bekasi , 29 Oktober 2025
B46: Ir. Supriyanto

Sheet REKAP
B1: REKAPITULASI RENCANA ANGGARAN BIAYA
B2: PEMILIK PROYEK | C2: : IBU LESTARI
B3: PROYEK | C3: : RUMAH TINGGAL 3 LANTAI
B4: LOKASI | C4: : CLUSTER MISSISSIPPI TE5 NO 8 KOWIS
B5: TYPE | C5: :
A6: NO | B6: URAIAN PEKERJAAN | D6: TOTAL HARGA
A9: III | B9: PEKERJAAN PEMBANGUNAN KONSTRUKSI
A10: A | B10: PEKERJAAN PERSIAPAN | D10: =RAB!H14 -> 2088000
A11: B | B11: PEKERJAAN PONDASI | D11: =RAB!H25 -> 6305625
A12: C | B12: PEKERJAAN STRUKTUR | D12: =RAB!H39 -> 36353700
A13: D | B13: PEKERJAAN DINDING | D13: =RAB!H43 -> 25800000
A14: E | B14: PEKERJAAN PELAPIS DINDING | D14: =RAB!H59 -> 42668000
A15: F | B15: PEKERJAAN ATAP | D15: =RAB!H73 -> 7677782.9
A16: G | B16: PEKERJAAN PLAFOND | D16: =RAB!H84 -> 528000
A17: H | B17: PEKERJAAN LANTAI | D17: =RAB!H120 -> 5345750
A18: I | B18: PEKERJAAN KUSEN, PINTU & JENDELA | D18: =RAB!H140 -> 0
A19: J | B19: PEKERJAAN KUNCI EX.DEKKSON | D19: =RAB!H146 -> 0
A20: K | B20: PEKERJAAN PENGECATAN | D20: =RAB!H153 -> 0
A21: L | B21: PEKERJAAN FINISHING TANGGA | D21: =RAB!H159 -> 420000
A22: M | B22: PEKERJAAN INSTALASI AIR | D22: =RAB!H173 -> 5560000
A23: N | B23: PEKERJAAN INSTALASI LISTRIK | D23: =RAB!H195 -> 0
A24: O | B24: PEKERJAAN ACCESSORIS SANITAIR | D24: =RAB!H213 -> 0
A25: P | B25: PEKERJAAN PAGAR & CANOPY | D25: =RAB!H223 -> 2377000
A26: Q | B26: PEKERJAAN PASANG PENANGKAL PETIR 2 TOMBAK | D26: =RAB!H229 -> 0
B27: SUB TOTAL | D27: =SUM(D10:D26) -> 1.3512386e+08
B28: JASA KONTRAKTOR | D28: =D27*0.1 -> 13512386
B29: TOTAL | D29: =D27+D28 -> 1.4863624e+08
B30: Dibulatkan | D30: =+ROUNDDOWN(D29,-6) -> 148000000
B32: Cibubur 23 Februari 2025
D33: Disetujui
B37: Ir. Supriyanto
D38: IBU LESTARI

Sheet RAB
B1: RENCANA ANGGARAN BIAYA
B2: PEMILIK PROYEK | C2: : IBU LESTARI
B3: PROYEK | C3: : RUMAH TINGGAL 3 LANTAI
B4: LOKASI | C4: : CLUSTER MISSISSIPPI TE5 NO 8 KOWIS
B5: TYPE | C5: :
A6: NO | B6: URAIAN PEKERJAAN | D6: URAIAN RINGKAS | E6: SAT. | F6: VOL | G6: HARGA SAT. | H6: TOTAL HARGA
G7: Rp | H7: Rp
A8: A | B8: PEKERJAAN PERSIAPAN
A9: 1 | B9: Direksi Keet & Gudang | D9: Rabat Beton, Seng, Triplek | E9: 1s | F9: 1 | G9: 800000 | H9: =F9*G9 -> 800000
A10: 2 | B10: Pas. Bouwplank | D10: Kayu Borneo | E10: m1 | F10: =(9+9)*2 -> 36 | G10: 8000 | H10: =F10*G10 -> 288000
A11: 3 | B11: Pembersihan | D11: Di Dalam Kavling | E11: 1s | F11: 1 | G11: 1000000 | H11: =F11*G11 -> 1000000
A12: 4 | B12: Air Kerja dan Listrik Kerja | D12: Selama Kerja | E12: 1s | F12: 1 | H12: =F12*G12 -> 0
A13: 5 | B13: Keamanan | D13: Selama Kerja | E13: 1s | F13: 1 | H13: =F13*G13 -> 0
D14: Sub Total A | H14: =SUM(H9:H13) -> 2088000
A15: B | B15: PEKERJAAN PONDASI
A16: 1 | B16: Galian Tanah | E16: m3 | F16: =(0.5*0.5*0.7)*17+(0.4*0.6*35) -> 11.375 | G16: 100000 | H16: =F16*G16 -> 1137500
A17: 2 | B17: Pemadatan tanah dasar pondasi | D17: Dengan stamper | E17: m2 | F17: =(0.5*0.5)*14+(0.4*35) -> 17.5 | H17: =F17*G17 -> 0
A18: 3 | B18: Urug Pasir Bawah Pondasi | D18: Pasir Urug Darat / t = 10 cm | E18: m3 | F18: =F17*0.05 -> 0.875 | G18: 40000 | H18: =F18*G18 -> 35000
A19: 4 | B19: Lt kerja t=5cm dibwh pondasi plat & sloof gantung | E19: m3 | F19: =F18 -> 0.875 | G19: 180000 | H19: =F19*G19 -> 157500
A20: 5 | B20: Pondasi Bor pile | D20: Ø 30 Cm Pj 4 m | E20: Bh | F20: =0.25*3.14*0.3*0.3*4*14 -> 3.9564 | H20: =F20*G20 -> 0
A21: 6 | B21: Sloof/Tie Beam | C21: 15/30 ( Besi 6 D 13 ) | D21: Site Mix K-225 | E21: m3 | F21: =0.15*0.3*68 -> 3.06 | G21: 900000 | H21: =F21*G21 -> 2754000
A22: 7 | B22: Pondasi Pile Cap | C22: D13-150 50x50x50 | D22: Site Mix K-225 | E22: m3 | F22: =0.5*0.5*0.5*17 -> 2.125 | G22: 900000 | H22: =F22*G22 -> 1912500
A23: 8 | B23: Urugan Tanah Kembali | D23: Padat Dengan Stamper Mesin | E23: m3 | F23: =F16/2 -> 5.6875 | G23: 6000 | H23: =F23*G23 -> 34125
A24: 9 | B24: Pas.Rollag | D24: Tinggi =40 Cm | E24: m1 | F24: =6+5 -> 11 | G24: 25000 | H24: =F24*G24 -> 275000
D25: Sub Total B | H25: =SUM(H16:H24) -> 6305625
A26: C | B26: PEKERJAAN STRUKTUR
A27: 1 | B27: Kolom Struktur | C27: Site Mix K-225
A28: 2 | B28: Kolom K1 15x40 Cm | C28: Besi 8 Ø 13 mm | D28: Site Mix K-225 | E28: m3 | F28: =(0.15*0.4*5*14)+(0.15*0.3*4*12)+(0.15*0.25*4*8) -> 7.56 | G28: 1000000 | H28: =F28*G28 -> 7560000
A29: 4 | B29: Kolom Praktis 12x12 Cm | C29: Besi 4 Ø 8 mm | D29: Site Mix K-225 | E29: m3 | F29: =(0.15*0.15*5*14)+(0.15*0.15*4*11)+(0.15*0.15*4*4) -> 2.925 | G29: 900000 | H29: =F29*G29 -> 2632500
A30: 5 | B30: Balok Lantai Atas | H30: =F30*G30 -> 0
A31: 6 | B31: Balok Lantai 2 B1 20x35 Cm | C31: Besi 7 Ø 13mm | D31: Redy Mix K225 | E31: m3 | F31: =(0.15*0.4*68)+(0.15*0.3*34) -> 5.61 | G31: 1000000 | H31: =F31*G31 -> 5610000
A32: 8 | B32: Ring Balk 15/20 Cm | C32: Besi 4 Ø 13mm | D32: Site Mix K-225 | E32: m3 | F32: =(0.15*0.2*34)+(0.15*0.2*34) -> 2.04 | G32: 1000000 | H32: =F32*G32 -> 2040000
A33: 9 | B33: Pelat Lantai Atas t= 12 cm | C33: Besi Ø 8-150 mm | D33: Redy Mix K225 | E33: m3 | F33: =(9*8*0.12)+(4*9*0.12) -> 12.96 | G33: 1000000 | H33: =F33*G33 -> 12960000
A34: 10 | B34: Beton Tangga Utama | D34: Redy Mix K225 | E34: m3 | F34: =6*1.2*0.15 -> 1.08 | G34: 1200000 | H34: =F34*G34 -> 1296000
A35: 11 | B35: Dak Talang t=10 cm | C35: Besi Ø 8-150 mm | D35: Site Mix K-225 | E35: m3 | F35: =(4*0.1*0.12*2)*2 -> 0.192 | G35: 900000 | H35: =F35*G35 -> 172800
A36: 12 | B36: Canopy & Konsol Jendela ( Lurus & lengkung ) diprofil+finishing | D36: Site Mix K-225 | E36: m3 | F36: =(3.5*1.5*0.12)+(3.2*1.5*0.12)+(1+5*1.5*0.1) -> 2.956 | G36: 900000 | H36: =F36*G36 -> 2660400
A37: 13 | B37: Meja Beton Dapur | D37: Site Mix K-225 | E37: m3 | F37: 0.58 | G37: 900000 | H37: =F37*G37 -> 522000
A38: 14 | B38: Balok Kongleong /Latai di atas Kusen | D38: Site Mix K-225 | E38: m3 | F38: 1 | G38: 900000 | H38: =F38*G38 -> 900000
D39: Sub Total C | H39: =SUM(H28:H38) -> 36353700
A40: D | B40: PEKERJAAN DINDING
...
